Workbook

Sheet Sheet2
A1: {=_xlfn.TOCOL(_xlfn.VSTACK([1]Электрическая!B$7:B$30,[1]Бомбардирующая!B$7:B$30,[1]Оружейная!B$7:B$30,[1]Сдерживающая!B$7:B$30,[1]Острая!B$7:B$30,[1]Перцовая!B$7:B$30,[1]Укрепительная!B$7:B$30,[1]Зимняя!B$7:B$30,[1]Магическая!B$7:B$30,[1]Успокаивающая!B$7:B$30,[1]Болезненная!B$7:B$30,[1]Принуждающая!B$7:B$30,[1]Скрытая!B$7:B$30,[1]Просветлённая!B$7:B$30),1,TRUE)} -> #VALUE! | B1: {=_xlfn.TOCOL(_xlfn.VSTACK([1]Электрическая!C$7:C$30,[1]Бомбардирующая!C$7:C$30,[1]Оружейная!C$7:C$30,[1]Сдерживающая!C$7:C$30,[1]Острая!C$7:C$30,[1]Перцовая!C$7:C$30,[1]Укрепительная!C$7:C$30,[1]Зимняя!C$7:C$30,[1]Магическая!C$7:C$30,[1]Успокаивающая!C$7:C$30,[1]Болезненная!C$7:C$30,[1]Принуждающая!C$7:C$30,[1]Скрытая!C$7:C$30,[1]Просветлённая!C$7:C$30),1,TRUE)} -> Электрический Горохострел | C1: {=_xlfn.TOCOL(_xlfn.VSTACK([1]Электрическая!D$7:D$30,[1]Бомбардирующая!D$7:D$30,[1]Оружейная!D$7:D$30,[1]Сдерживающая!D$7:D$30,[1]Острая!D$7:D$30,[1]Перцовая!D$7:D$30,[1]Укрепительная!D$7:D$30,[1]Зимняя!D$7:D$30,[1]Магическая!D$7:D$30,[1]Успокаивающая!D$7:D$30,[1]Болезненная!D$7:D$30,[1]Принуждающая!D$7:D$30,[1]Скрытая!D$7:D$30,[1]Просветлённая!D$7:D$30),1,TRUE)} -> 300 | D1: {=_xlfn.TOCOL(_xlfn.VSTACK([1]Электрическая!E$7:E$30,[1]Бомбардирующая!E$7:E$30,[1]Оружейная!E$7:E$30,[1]Сдерживающая!E$7:E$30,[1]Острая!E$7:E$30,[1]Перцовая!E$7:E$30,[1]Укрепительная!E$7:E$30,[1]Зимняя!E$7:E$30,[1]Магическая!E$7:E$30,[1]Успокаивающая!E$7:E$30,[1]Болезненная!E$7:E$30,[1]Принуждающая!E$7:E$30,[1]Скрытая!E$7:E$30,[1]Просветлённая!E$7:E$30),1,TRUE)} -> 50 | E1: {=_xlfn.TOCOL(_xlfn.VSTACK([1]Электрическая!F$7:F$30,[1]Бомбардирующая!F$7:F$30,[1]Оружейная!F$7:F$30,[1]Сдерживающая!F$7:F$30,[1]Острая!F$7:F$30,[1]Перцовая!F$7:F$30,[1]Укрепительная!F$7:F$30,[1]Зимняя!F$7:F$30,[1]Магическая!F$7:F$30,[1]Успокаивающая!F$7:F$30,[1]Болезненная!F$7:F$30,[1]Принуждающая!F$7:F$30,[1]Скрытая!F$7:F$30,[1]Просветлённая!F$7:F$30),1,TRUE)} -> 20 | F1: {=_xlfn.TOCOL(_xlfn.VSTACK([1]Электрическая!G$7:G$30,[1]Бомбардирующая!G$7:G$30,[1]Оружейная!G$7:G$30,[1]Сдерживающая!G$7:G$30,[1]Острая!G$7:G$30,[1]Перцовая!G$7:G$30,[1]Укрепительная!G$7:G$30,[1]Зимняя!G$7:G$30,[1]Магическая!G$7:G$30,[1]Успокаивающая!G$7:G$30,[1]Болезненная!G$7:G$30,[1]Принуждающая!G$7:G$30,[1]Скрытая!G$7:G$30,[1]Просветлённая!G$7:G$30),1,TRUE)} -> 20 | G1: {=_xlfn.TOCOL(_xlfn.VSTACK([1]Электрическая!H$7:H$30,[1]Бомбардирующая!H$7:H$30,[1]Оружейная!H$7:H$30,[1]Сдерживающая!H$7:H$30,[1]Острая!H$7:H$30,[1]Перцовая!H$7:H$30,[1]Укрепительная!H$7:H$30,[1]Зимняя!H$7:H$30,[1]Магическая!H$7:H$30,[1]Успокаивающая!H$7:H$30,[1]Болезненная!H$7:H$30,[1]Принуждающая!H$7:H$30,[1]Скрытая!H$7:H$30,[1]Просветлённая!H$7:H$30),1,TRUE)} -> Electro Cannon | H1: {=_xlfn.TOCOL(_xlfn.VSTACK([1]Электрическая!I$7:I$30,[1]Бомбардирующая!I$7:I$30,[1]Оружейная!I$7:I$30,[1]Сдерживающая!I$7:I$30,[1]Острая!I$7:I$30,[1]Перцовая!I$7:I$30,[1]Укрепительная!I$7:I$30,[1]Зимняя!I$7:I$30,[1]Магическая!I$7:I$30,[1]Успокаивающая!I$7:I$30,[1]Болезненная!I$7:I$30,[1]Принуждающая!I$7:I$30,[1]Скрытая!I$7:I$30,[1]Просветлённая!I$7:I$30),1,TRUE)} -> Наносит 70% урона основной цели и 40% всем под целям. С каждым ходом, что этот юнит не атаковал увеличивает урон в 2,3,4 раза. | ... O1: {=_xlfn.TOCOL(_xlfn.VSTACK([1]Электрическая!P$7:P$30,[1]Бомбардирующая!P$7:P$30,[1]Оружейная!P$7:P$30,[1]Сдерживающая!P$7:P$30,[1]Острая!P$7:P$30,[1]Перцовая!P$7:P$30,[1]Укрепительная!P$7:P$30,[1]Зимняя!P$7:P$30,[1]Магическая!P$7:P$30,[1]Успокаивающая!P$7:P$30,[1]Болезненная!P$7:P$30,[1]Принуждающая!P$7:P$30,[1]Скрытая!P$7:P$30,[1]Просветлённая!P$7:P$30),1,TRUE)} -> Электрическое
A2: #VALUE! | B2: Электро-Камыш | C2: 220 | D2: 20 | E2: 20 | F2: 10 | G2: Shock | H2: Наносит 30% урона всем врагам. | I2: None | J2: None | K2: None | L2: None | M2: Nimbus | N2: Вызывает шторм, что наносит 30 Разряда каждый ход. 4 Хода. | O2: Электрическое
A3: #VALUE! | B3: Кортофельная Мина | C3: 200 | D3: 900 | E3: 0 | F3: 100 | G3: Mine Sting | H3: Наносит 30% урона. | I3: None | J3: None | K3: None | L3: None | M3: Spudow! | N3: Наносит 1000% урона всем Зомби, затем погибает. | O3: Бомбардирующее
A4: #VALUE! | B4: Вишнёвая Бомба | C4: 300 | D4: 1800 | E4: 0 | F4: 100 | G4: CHA-BOOF! | H4: Наносит 100% урона всем Зомби, затем погибает. | I4: None | J4: None | K4: None | L4: None | M4: None | N4: None | O4: Бомбардирующее
A5: #VALUE! | B5: Граната | C5: 300 | D5: 1800 | E5: 0 | F5: 100 | G5: POOF! | H5: Наносит 80% урона всем Зомби, затем погибает. | I5: None | J5: None | K5: Granate | L5: Призывает 3 Гранатиков при гибели. | M5: None | N5: None | O5: Бомбардирующее
A6: #VALUE! | B6: Гранатики | C6: 50 | D6: 100 | E6: 0 | F6: 50 | G6: Poof | H6: Наносит 70% урона, затем погибает. | I6: None | J6: None | K6: None | L6: None | M6: None | N6: None | O6: Бомбардирующее
A7: #VALUE! | B7: Капустопульта | C7: 300 | D7: 30 | E7: 50 | F7: 20 | G7: Cabbage Hurl | H7: Наносит 125% урона. | I7: Cabage Growth | J7: Все Растения наносит +30% урона. 1 Ход. | K7: None | L7: None | M7: Cabbage Rain | N7: Наносит 300% урона всем врагам. | O7: Оружейное
A8: #VALUE! | B8: Зернопульта | C8: 300 | D8: 30 | E8: 50 | F8: 15 | G8: Cob Buster | H8: Наносит 100% урона. С шансом в 25% может швырнуть Масло, что нанесёт 200% урона и 4 Масло. | I8: Husky Hop | J8: Выбранное Растение наносит +30% урона, но получает +30% урона. 3 Хода. | K8: None | L8: None | M8: Butter Barrage | N8: Наносит 200% урона и 10 Масло на всех врагов. | O8: Оружейное
A9: #VALUE! | B9: Взрывоягодная Лоза | C9: 300 | D9: 50 | E9: 50 | F9: 10 | G9: Berry Bombard | H9: Наносит 80% урона. | I9: Blastberry Vine | J9: Размещается на выбранном Растение. Если Растение Оружейного Семейства, Headshot активируется с 15% от макс HP. | K9: Vine | L9: Считается за 0,5 Слота Семян, но имеет -50% базовых характеристик. | M9: Arma Ready | N9: Дублирует Удобрение Растения Оружейного Семейства. | O9: Оружейное
A10: #VALUE! | B10: Кокосовая Пушка | C10: 800 | D10: 900 | E10: 140 | F10: 100 | G10: Nut Launch | H10: Наносит 90% урона Основной Цели и 50% всем остальным, затем Оглушается. | I10: None | J10: None | K10: Hard Shell | L10: Получает -20% урона. | M10: Cannon Ball | N10: Наносит 200% урона Основной Цели и 100% всем остальным, затем Оглушается. | O10: Оружейное
A11: #VALUE! | B11: Яблочная Мортира | C11: 400 | D11: 100 | E11: 50 | F11: 20 | G11: Apple Discharge | H11: Наносит 40% урона трём целям. | I11: None | J11: None | K11: Apple of Eden | L11: С шансом в 30% сбрасывает один заряд с Заряжаемого действия. | M11: Apple Rain | N11: Наносит 100% урона всем целям. С шансом в 50% Оглушает цель. | O11: Оружейное
A12: #VALUE! | B12: Арбузопульта | C12: 300 | D12: 50 | E12: 50 | F12: 15 | G12: Melon Hit | H12: Наносит 300% урона Основной Цели и 100% всем остальным. | I12: Melon Shield | J12: Выбранное Растение получает Shield равный 30% макс HP. | K12: None | L12: None | M12: Melon Storm | N12: Наносит 500% урона Основной Цели и 100% урона всем остальным. Атакует каждую цель. | O12: Оружейное
A13: #VALUE! | B13: Могильный Разрушитель | C13: 500 | D13: None | E13: 50 | F13: None | G13: Stone Bite | H13: Наносит 200% урона. | I13: None | J13: None | K13: Grave Destroyer | L13: Наносит +500% урона Надгробиям. | M13: None | N13: None | O13: Сдерживающее
A14: #VALUE! | B14: Пружинистый Боб | C14: 200 | D14: 50 | E14: 50 | F14: 20 | G14: None | H14: None | I14: None | J14: None | K14: Spring Push | L14: Когда атакован отбрасывает Зомби отменяю атаку, затем Оглушается. | M14: Spring Jump | N14: Обнуляет заряд всех Зомби. | O14: Сдерживающее
A15: #VALUE! | B15: Сквознецис | C15: 290 | D15: None | E15: 40 | F15: None | G15: Gust | H15: Наносит 50% урона. Если враг летающий наносит 200% урона. | I15: None | J15: None | K15: Downdraft | L15: Все летающие Зомби должны заряжать каждое действие. Если действие уже было заряжаемым, то оно увеличиывется на 1. | M15: Huricane | N15: Наносит 50% урона. Если враг летающий мгновенно убивает. | O15: Сдерживающее
A16: #VALUE! | B16: Ураганная Капуста | C16: 200 | D16: None | E16: 50 | F16: None | G16: Arctic Wind | H16: Наносит 20 Заморозки. | I16: None | J16: None | K16: None | L16: None | M16: Absolute Zero | N16: Замораживает всех Зомби. | O16: Сдерживающее
A17: #VALUE! | B17: Ошеломительный Лук | C17: 200 | D17: 20 | E17: 50 | F17: 10 | G17: Paralyzing Gas | H17: Наносит 5 Яд. С шансом в (40 + Яд)% Оглушает цель, если Оглушил цель погибает | I17: None | J17: None | K17: None | L17: None | M17: None | N17: None | O17: Сдерживающее
A18: #VALUE! | B18: Цветущий Бумеранг | C18: 300 | D18: 20 | E18: 50 | F18: 10 | G18: Boomerang Throw | H18: Наносит 100% x2 урона 2 врагам. | I18: Tornado | J18: Выбранное Растение выполняет Атаку. | K18: None | L18: None | M18: Boomerang Rush | N18: Выполняет 5 атак по случайным целям. | O18: Острое
A19: #VALUE! | B19: Колючки | C19: 300 | D19: 20 | E19: 50 | F19: 10 | G19: Spike | H19: Наносит 50% x5 урона. | I19: Weed Sector | J19: Атакует цель, что атаковала выбранное Растение. 3 Хода | K19: None | L19: None | M19: Spikeweed Sector | N19: Наносит 3 Атаки по всем Зомби. | O19: Острое
A20: #VALUE! | B20: Каменные Колючки | C20: 700 | D20: 30 | E20: 150 | F20: 10 | G20: Spear | H20: Наносит 100% x5 урона. | I20: Rock Sector | J20: Атакует цель, что атаковала выбранное Растение. Выбранное Растение получает -30% урона. 2 Хода | K20: None | L20: None | M20: Spikerock Sector | N20: Наносит 4 Атаки по всем Зомби. | O20: Острое
A21: #VALUE! | B21: Заводной Жёлудь | C21: 350 | D21: 30 | E21: 70 | F21: 10 | G21: Clockwork | H21: Наносит 100% x2 урона 2 врагам. С каждым ходом, что этот юнит не атаковал увеличивает урон +20%. | I21: None | J21: None | K21: Widing Power | L21: С каждым ходом, что этот юнит не тратил действие увеличивает шанс Оглушения. | M21: Rapid Rotation | N21: Выполняет 5 атак по случайным целям. | O21: Острое
A22: #VALUE! | B22: Львиный Зев | C22: 300 | D22: 20 | E22: 50 | F22: 10 | G22: Dragon Breath | H22: Наносит 150% урона и 10 Горения 3 целям. | I22: Blazing Trail | J22: Атакующий получает 35 Горения при атаке выбранного Растения. 2 Хода. | K22: None | L22: None | M22: Infernal Breath | N22: Наносит (50 * Горение)% урона всем Зомби. | O22: Перцовое
A23: #VALUE! | B23: Огненный Горохострел | C23: 400 | D23: 60 | E23: 60 | F23: 30 | G23: Flame Pea | H23: Наносит 200% урона и 20 Горения. | I23: None | J23: None | K23: Peashooter | L23: Считается Растением Успокаивающегося Семейства | M23: Fire Stream | N23: Наносит 70 Горения всем Зомби. | O23: Перцовое
A24: #VALUE! | B24: Пиро Лоза | C24: 200 | D24: 60 | E24: 200 | F24: 30 | G24: Flamethrower | H24: Наносит 50% урона и 5 Горения всем целям с Горением. | I24: Pyro Vine | J24: Размещается на выбранном Растение. Если Растение Перцового Семейства, Растение наносит *2 урона. | K24: Vine | L24: Считается за 0,5 Слота Семян, но имеет -50% базовых характеристик. | M24: Pyromancy | N24: Наносит 100% урона всем целям с Горением. | O24: Перцовое
A25: #VALUE! | B25: Халапеньо | C25: 2000 | D25: 60 | E25: 100 | F25: 30 | G25: So SPICY!!! | H25: Наносит (1000 * (Горение / 5)% урона всем Зомби, затем погибает. | I25: None | J25: None | K25: None | L25: None | M25: None | N25: None | O25: Перцовое
A26: #VALUE! | B26: Горячая Картошка | C26: 4000 | D26: 200 | E26: 100 | F26: 50 | G26: None | H26: None | I26: Warmth | J26: Снимает всё Обморожение с Растения. | K26: None | L26: None | M26: None | N26: None | O26: Перцовое
A27: #VALUE! | B27: Перцепульта | C27: 1000 | D27: 5 | E27: 100 | F27: 30 | G27: Pepper Throw | H27: Наносит 125% урона и 10 Горения. | I27: Pepper Growth | J27: Все Растения наносят 5 Горения. 3 Хода. | K27: Catapult | L27: Считается Растением Оружейного Семейства | M27: Pepper Rain | N27: Наносит 300% урона и 50 Горения всем врагам. | O27: Перцовое
A28: #VALUE! | B28: Халапеньо | C28: 1600 | D28: 40 | E28: 100 | F28: 10 | G28: So SPICY!!! | H28: Наносит (1000 * (Горение / 5)% урона всем Зомби, затем погибает. | I28: None | J28: None | K28: None | L28: None | M28: None | N28: None | O28: Перцовое
... A30: #VALUE! | B30: Высокий Орех | C30: 200 | D30: 30 | E30: 50 | F30: 20 | G30: Wall Smash | H30: Наносит 150% урона. | I30: Wall | J30: Защищает выбранное Растения от атак. 3 Хода. | K30: None | L30: None | M30: Steel Wall | N30: Получает Барьер в 100% макс HP и исцеляется на 100% текущего HP. | O30: Укрепительное
A31: #VALUE! | B31: Мангольд Страж | C31: 300 | D31: None | E31: 50 | F31: None | G31: Leafy Push | H31: Наносит 100% урона. С шансом в 50% отменяет 1 Заряд. | I31: None | J31: None | K31: Guard | L31: Может атаковать только 3 раза, затем теряет атаку. | M31: CHARD! | N31: Атакует всех Зомби и востанавливает возможность к атаке. | O31: Укрепительное
A32: #VALUE! | B32: Отряд Каштанов | C32: 450 | D32: None | E32: 50 | F32: None | G32: None | H32: None | I32: Nut Release | J32: Выпускает 4 Каштана на выбранное Растение. | K32: None | L32: None | M32: Nuts Squad | N32: Наносит 500% урона всем Зомби. | O32: Укрепительное
A33: #VALUE! | B33: Группа Каштанов | C33: 400 | D33: None | E33: 50 | F33: None | G33: Chestnut Jump | H33: Наносит 100% x(Каштанов в группе) урона. | I33: None | J33: None | K33: None | L33: None | M33: None | N33: None | O33: Укрепительное
A34: #VALUE! | B34: Салат Айсберг | C34: 100 | D34: 30 | E34: 100 | F34: 20 | G34: Chill | H34: Наносит 50% урона и наносит 10 Обморожения. | I34: None | J34: None | K34: None | L34: None | M34: Ice Chunks | N34: Все Зомби получают 100% урона и 100 Обморожения. | O34: Зимнее
A35: #VALUE! | B35: Ледяной Горохострел | C35: 400 | D35: 30 | E35: 100 | F35: 20 | G35: Ice Pea | H35: Наносит (100 + Обморожение)% урона и наносит 20 Обморожения. | I35: None | J35: None | K35: Peashooter | L35: Считается Растением Успокаивающегося Семейства | M35: Snow Gatling | N35: Наносит 20% и 5 Обморожения x20 урона случайной целе. | O35: Зимнее
A36: #VALUE! | B36: Ледяной Зев | C36: 600 | D36: 40 | E36: 50 | F36: 15 | G36: Ice Breath | H36: Наносит (50 + Обморожение)% урона и наносит 15 Обморожения 3 целям. | I36: Cold Fur | J36: Выбранное Растение не может быть Замороженно. 3 Хода. | K36: Icicles | L36: При убийстве наносит 30 Обморожения всем Зомби. | M36: Ice Age | N36: Наносит (50 * Обморожение)% урона всем Зомби. | O36: Зимнее
A37: #VALUE! | B37: Ледяная Арбузопульта | C37: 300 | D37: 60 | E37: 50 | F37: 20 | G37: Frozen Melon | H37: Наносит 200% урона Основной Цели и 10 Заморозки и 50% урона всем остальным и 5 Заморозки. | I37: Cold Fruit | J37: Выбранное Растение получает 30 Заморозки и Shield равный 50% макс HP. | K37: Catapult | L37: Считается Растением Оружейного Семейства | M37: Winter Storm | N37: Наносит 500% урона Основной Цели и 100% урона всем остальным, а также 50 Заморозки. Атакует каждую цель. | O37: Зимнее
A38: #VALUE! | B38: Ромашка | C38: 300 | D38: 30 | E38: 50 | F38: 20 | G38: None | H38: None | I38: None | J38: None | K38: Magical Sprout | L38: Превращается в случайное Растение этой эпохи. | M38: None | N38: None | O38: Магическое
A39: #VALUE! | B39: Силовая Лилия | C39: 1500 | D39: 20 | E39: 50 | F39: 20 | G39: None | H39: None | I39: None | J39: None | K39: Fertilyze | L39: Выдаёт 1 Удобрение каждые 3 Хода. | M39: Procreation | N39: Выдаёт 3 Удобрения, после чего исчезает. | O39: Магическое
A40: #VALUE! | B40: Имитатор | C40: 300 | D40: 30 | E40: 50 | F40: 25 | G40: None | H40: None | I40: None | J40: None | K40: Copy | L40: Копирует первое дейстующее Растение. | M40: None | N40: None | O40: Магическое
A41: #VALUE! | B41: Горохострел | C41: 300 | D41: 40 | E41: 50 | F41: 30 | G41: Pea Shot | H41: Наносит 100% урона. | I41: None | J41: None | K41: None | L41: None | M41: Gatling | N41: Наносит 80% x20 урона. | O41: Успокаивающее
...

Sheet Растения
B2: Вид | C2: Имя | D2: Атака | F2: Защита | H2: Пассивная Способность | J2: Удобрение | L2: Семейство
D3: Название | E3: Описание | F3: Название | G3: Описание | H3: Название | I3: Описание | J3: Название | K3: Описание
B4: =_xlfn.XLOOKUP(C4,Sheet2!B:B,Sheet2!A:A) -> #VALUE! | C4: Горохострел | D4: {=_xlfn.XLOOKUP(C4,Sheet2!B:B,Sheet2!G:O,"NONE",0,1)} -> Pea Shot | E4: Наносит 100% урона. | F4: None | G4: None | H4: None | I4: None | J4: Gatling | K4: Наносит 80% x20 урона. | L4: Успокаивающее
B5: макс HP | C5: Текущее HP | D5: HP% | E5: Полученный урон | F5: Атака
B6: {=_xlfn.XLOOKUP(C4,Sheet2!B:B,Sheet2!C:C+Sheet2!E:E*Растения!B8,0,0,1)} -> 400 | C6: =B6-E6 -> 400 | D6: =_xlfn.PERCENTOF(C6,B6) -> 1 | E6: 0 | F6: {=_xlfn.XLOOKUP(C4,Sheet2!B:B,Sheet2!D:D+Sheet2!F:F*(Растения!B8-1),0,0,1)} -> 70
B7: LV | C7: Действует | D7: Эффекты
B8: 2 | C8: "Yes" | D8: Название | E8: Описание | F8: Длительность

Sheet Калькулятор
B2: Урон | I2: Удобрения
B3: Атака | C3: % | D3: -% | E3: +% | F3: Горение | G3: Итого | I3: Растений | J3: Уровень | K3: Итого
B4: 24 | C4: 0.2 | F4: 10 | G4: =$B$4*$C$4+($B$4*$D$4)-($B$4*$E$4)+$F$4 -> 14.8 | I4: 2 | J4: =Растения!B8 -> 2 | K4: =I4*J4*100 -> 400
B6: Лечение
B7: HP | C7: % | F7: Итого
F8: =$B$8*$C$8+($B$8*$D$8)-($B$8*$E$8) -> 0

Sheet Зомби
